<?xml version='1.0'?>
<robot name="creation">

    <!-- Colors --> 
    <material name="black"> 
        <color rgba="0 0 0 1"/>
    </material>
    <material name="blue"> 
        <color rgba="0.6 0.7 0.8 1"/>
    </material>

    <!-- Base Link -->
    <link name="base_link">
        <visual>
            <geometry>
                <box size="0.3 0.2 0.07"/>
            </geometry>
            <material name="blue"/>
        </visual>
        <collision>
            <geometry>
                <box size="0.3 0.2 0.07"/>
            </geometry>
        </collision>
        <inertial>
            <mass value="0.6"/>
            <inertia ixx="0.0007" ixy="0" ixz="0" iyy="0.0047" iyx="0" izz="0.005"/>
        </inertial>
    </link>

    <!-- Left Hind Thigh -->
    <link name="left_hind_thigh">
        <visual>
            <geometry>
                <box size="0.03 0.01 0.1"/>
            </geometry>
            <origin xyz="0 0 -0.03"/>
            <material name="black"/>
        </visual>
        <collision>
            <geometry>
                <box size="0.03 0.01 0.1"/>
            </geometry>
            <origin xyz="0 0 -0.03"/>
        </collision>
        <inertial>
            <mass value="0.07"/>
            <inertia ixx="0.000058917" ixy="0" ixz="0" iyy="0.000063583" iyz="0" izz="6.5E-6"/>
        </inertial>
    </link>
    <joint name="base_to_left_hind_thigh" type="revolute">
        <parent link="base_link"/>
        <child link="left_hind_thigh"/>
        <axis xyz="0 1 0"/>
        <origin xyz="-0.08 -0.105 -0.035"/>
        <limit effort="100" lower="-1.05" upper="1.05" velocity="5.23"/>
    </joint>

    <!-- Left Hind Calf -->
    <link name="left_hind_calf">
        <visual>
            <geometry>
                <box size="0.03 0.015 0.1"/>
            </geometry>
            <material name="blue"/>
            <origin xyz="0 -0.0075 -0.05"/>
        </visual>
        <collision>
            <geometry>
                <box size="0.03 0.015 0.1"/>
            </geometry>
            <origin xyz="0 -0.0075 -0.05"/>
        </collision>
        <inertial>
            <mass value="0.02"/>
            <inertia ixx="1 .7E-5" ixy="0" ixz="0" iyy="3.9E-5" iyz="0" izz="1.9E-6"/>
        </inertial>
    </link>
    <joint name="left_hind_knee" type="revolute">
        <parent link="left_hind_thigh"/>
        <child link="left_hind_calf"/>
        <axis xyz="0 1 0"/>
        <origin xyz="0 -0.0075 -0.05"/>
        <limit effort="100" lower="0" upper="2.1" velocity="5.23"/>
    </joint>

    <!-- Left Hind Foot -->
    <link name="left_hind_foot">
        <visual>
            <geometry>
                <cylinder length="0.03" radius="0.015"/>
            </geometry>
            <material name="black"/>
            <origin rpy="1.57075 1.57075 0"/>
        </visual>
        <collision>
            <geometry>
                <cylinder length="0.03" radius="0.015"/>
            </geometry>
        </collision>
        <inertial>
            <mass value="0.01"/>
            <inertia ixx="1.8E-5" ixy="0" ixz="0" iyy="2E-5" iyz="0" izz="9.3E-7"/>
        </inertial>
    </link>
    <joint name="calf_to_foot_left_hind" type="fixed">
        <parent link="left_hind_calf"/>
        <child link="left_hind_foot"/>
        <origin xyz="0 -0.0075 -0.1"/>
    </joint>





    <!-- Right Hind Thigh -->
    <link name="right_hind_thigh">
        <visual>
            <geometry>
                <box size="0.03 0.015 0.1"/>
            </geometry>
            <origin xyz="0 0 -0.03" />
            <material name="black"/>
        </visual>
        <collision>
            <geometry>
                <box size="0.03 0.015 0.1"/>
            </geometry>
            <origin xyz="0 0 -0.03"/>
        </collision>
        <inertial>
            <mass value="0.07"/>
            <inertia ixx="0.000058917" ixy="0" ixz="0" iyy="0.000063583" iyz="0" izz="6.5E-6"/>
        </inertial>
    </link>
    <joint name="base_to_right_hind_thigh" type="revolute">
        <parent link="base_link"/>
        <child link="right_hind_thigh"/>
        <axis xyz="0 1 0"/>
        <origin xyz="-0.08 0.105 -0.035"/>
        <limit effort="100" lower="-1.05" upper="1.05" velocity="5.23"/>
    </joint>

    <!-- Right Hind Calf -->
    <link name="right_hind_calf">
        <visual>
            <geometry>
                <box size="0.03 0.015 0.1"/>
            </geometry>
            <material name="blue"/>
            <origin xyz="0 0.0075 -0.05" />
        </visual>
        <collision>
            <geometry>
                <box size="0.03 0.015 0.1"/>
            </geometry>
            <origin xyz="0 0.0075 -0.05"/>
        </collision>
        <inertial>
            <mass value="0.02"/>
            <inertia ixx="3.7E-5" ixy="0" ixz="0" iyy="3.9E-5" iyz="0" izz="1.9E-6"/>
        </inertial>
    </link>
    <joint name="right_hind_knee" type="revolute">
        <parent link="right_hind_thigh"/>
        <child link="right_hind_calf"/>
        <axis xyz="0 1 0"/>
        <origin xyz="0 0.0075 -0.05"/>
        <limit effort="100" lower="0" upper="2.1" velocity="5.23"/>
    </joint>

    <!-- Right Hind Foot -->
    <link name="right_hind_foot">
        <visual>
            <geometry>
                <cylinder length="0.03" radius="0.015"/>
            </geometry>
            <material name="black"/>
            <origin rpy="1.57075 1.57075 0"/>
        </visual>
        <collision>
            <geometry>
                <cylinder length="0.03" radius="0.015"/>
            </geometry>
        </collision>
        <inertial>
            <mass value="0.01"/>
            <inertia ixx="1.8E-5" ixy="0" ixz="0" iyy="2E-5" iyz="0" izz="9.3E-7"/>
        </inertial>
    </link>
    <joint name="calf_to_foot_right_hind" type="fixed">
        <parent link="right_hind_calf"/>
        <child link="right_hind_foot"/>
        <origin xyz="0 0.0075 -0.1"/>
    </joint>





    <!-- Left Front Thigh -->
    <link name="left_front_thigh">
        <visual>
            <geometry>
                <box size="0.03 0.015 0.1"/>
            </geometry>
            <origin xyz="0 0 -0.03"/>
            <material name="black"/>
        </visual>
        <collision>
            <geometry>
                <box size="0.03 0.015 0.1"/>
            </geometry>
            <origin xyz="0 0 -0.03"/>
        </collision>
        <inertial>
            <mass value="0.07"/>
            <inertia ixx="0.000058917" ixy="0" ixz="0" iyy="0.000063583" iyz="0" izz="6.5E-6"/>
        </inertial>
    </link>
    <joint name="base_to_left_front_thigh" type="revolute">
        <parent link="base_link"/>
        <child link="left_front_thigh"/>
        <axis xyz="0 1 0"/>
        <origin xyz="0.08 -0.105 -0.035"/>
        <limit effort="100" lower="-1.05" upper="1.05" velocity="5.23"/>
    </joint>

    <!-- Left Front Calf -->
    <link name="left_front_calf">
        <visual>
            <geometry>
                <box size="0.03 0.015 0.1"/>
            </geometry>
            <material name="blue"/>
            <origin xyz="0 -0.0075 -0.05"/>
        </visual>
        <collision>
            <geometry>
                <box size="0.03 0.015 0.1"/>
            </geometry>
            <origin xyz="0 -0.0075 -0.05"/>
        </collision>
        <inertial>
            <mass value="0.02"/>
            <inertia ixx="3.7E-5" ixy="0" ixz="0" iyy="3.9E-5" iyz="0" izz="1.9E-6"/>
        </inertial>
    </link>
    <joint name="left_front_knee" type="revolute">
        <parent link="left_front_thigh"/>
        <child link="left_front_calf"/>
        <axis xyz="0 1 0"/>
        <origin xyz="0 -0.0075 -0.05"/>
        <limit effort="100" lower="0" upper="2.1" velocity="5.23"/>
    </joint>

    <!-- Left Front Foot -->
    <link name="left_front_foot">
        <visual>
            <geometry>
                <cylinder length="0.03" radius="0.015"/>
            </geometry>
            <material name="black"/>
            <origin rpy="1.57075 1.57075 0"/>
        </visual>
        <collision>
            <geometry>
                <cylinder length="0.03" radius="0.015"/>
            </geometry>
        </collision>
        <inertial>
            <mass value="0.01"/>
            <inertia ixx="1.8E-5" ixy="0" ixz="0" iyy="2E-5" iyz="0" izz="9.3E-7"/>
        </inertial>
    </link>
    <joint name="calf_to_foot_left_front" type="fixed">
        <parent link="left_front_calf"/>
        <child link="left_front_foot"/>
        <origin xyz="0 -0.0075 -0.1"/>
    </joint>





    <!-- Right Front Thigh -->
    <link name="right_front_thigh">
        <visual>
            <geometry>
                <box size="0.03 0.015 0.1"/>
            </geometry>
            <origin xyz="0 0 -0.03"/>
            <material name="black"/>
        </visual>
        <collision>
            <geometry>
                <box size="0.03 0.015 0.1"/>
            </geometry>
            <origin xyz="0 0 -0.03"/>
        </collision>
        <inertial>
            <mass value="0.07"/>
            <inertia ixx="0.000058917" ixy="0" ixz="0" iyy="0.000063583" iyz="0" izz="6.5E-6"/>
        </inertial>
    </link>
    <joint name="base_to_right_front_thigh" type="revolute">
        <parent link="base_link"/>
        <child link="right_front_thigh"/>
        <axis xyz="0 1 0"/>
        <origin xyz="0.08 0.105 -0.035"/>
        <limit effort="100" lower="-1.05" upper="1.05" velocity="5.23"/>
    </joint>

    <!-- Right Front Calf -->
    <link name="right_front_calf"> 
        <visual>
            <geometry>
                <box size="0.03 0.015 0.1"/>
            </geometry>
            <material name="blue"/>
            <origin xyz="0 0.0075 -0.05"/>
        </visual>
        <collision>
            <geometry>
                <box size="0.03 0.015 0.1"/>
            </geometry>
            <origin xyz="0 0.0075 -0.05"/>
        </collision>
        <inertial>
            <mass value="0.02"/>
            <inertia ixx="3.7E-5" ixy="0" ixz="0" iyy="3.9E-5" iyz="0" izz="1.9E-6"/>
        </inertial>
    </link>
    <joint name="right_front_knee" type="revolute">
        <parent link="right_front_thigh"/>
        <child link="right_front_calf"/>
        <axis xyz="0 1 0"/>
        <origin xyz="0 0.0075 -0.05"/>
        <limit effort="100" lower="0" upper="2.1" velocity="5.23"/>
    </joint>

    <!-- Right Front Foot -->
    <link name="right_front_foot">
        <visual>
            <geometry>
                <cylinder length="0.03" radius="0.015"/>
            </geometry>
            <material name="black"/>
            <origin rpy="1.57075 1.57075 0"/>
        </visual>
        <collision>
            <geometry>
                <cylinder length="0.03" radius="0.015"/>
            </geometry>
        </collision>
        <inertial>
            <mass value="0.01"/>
            <inertia ixx="1.8E-5" ixy="0" ixz="0" iyy="2E-5" iyz="0" izz="9.3E-7"/>
        </inertial>
    </link>
    <joint name="calf_to_foot_right_front" type="fixed">
        <parent link="right_front_calf"/>
        <child link="right_front_foot"/>
        <origin xyz="0 0.0075 -0.1"/>
    </joint>
</robot>
